{"level":"error","message":"❌ PostgreSQL connection failed: password authentication failed for user \"username\"","name":"SequelizeConnectionError","original":{"code":"28P01","file":"auth.c","length":104,"line":"332","name":"error","routine":"auth_failed","severity":"FATAL"},"parent":{"code":"28P01","file":"auth.c","length":104,"line":"332","name":"error","routine":"auth_failed","severity":"FATAL"},"service":"cv-builder-api","stack":"SequelizeConnectionError: password authentication failed for user \"username\"\n    at Client._connectionCallback (D:\\Resume _Generator\\backend\\node_modules\\sequelize\\src\\dialects\\postgres\\connection-manager.js:196:24)\n    at Client._handleErrorWhileConnecting (D:\\Resume _Generator\\backend\\node_modules\\pg\\lib\\client.js:336:19)\n    at Client._handleErrorMessage (D:\\Resume _Generator\\backend\\node_modules\\pg\\lib\\client.js:356:19)\n    at Connection.emit (node:events:518:28)\n    at Connection.emit (node:domain:489:12)\n    at D:\\Resume _Generator\\backend\\node_modules\\pg\\lib\\connection.js:116:12\n    at Parser.parse (D:\\Resume _Generator\\backend\\node_modules\\pg-protocol\\src\\parser.ts:103:9)\n    at Socket.<anonymous> (D:\\Resume _Generator\\backend\\node_modules\\pg-protocol\\src\\index.ts:7:48)\n    at Socket.emit (node:events:518:28)\n    at Socket.emit (node:domain:489:12)","timestamp":"2025-09-04T12:47:12.302Z"}
{"level":"error","message":"❌ PostgreSQL connection failed: password authentication failed for user \"username\"","name":"SequelizeConnectionError","original":{"code":"28P01","file":"auth.c","length":104,"line":"332","name":"error","routine":"auth_failed","severity":"FATAL"},"parent":{"code":"28P01","file":"auth.c","length":104,"line":"332","name":"error","routine":"auth_failed","severity":"FATAL"},"service":"cv-builder-api","stack":"SequelizeConnectionError: password authentication failed for user \"username\"\n    at Client._connectionCallback (D:\\Resume _Generator\\backend\\node_modules\\sequelize\\src\\dialects\\postgres\\connection-manager.js:196:24)\n    at Client._handleErrorWhileConnecting (D:\\Resume _Generator\\backend\\node_modules\\pg\\lib\\client.js:336:19)\n    at Client._handleErrorMessage (D:\\Resume _Generator\\backend\\node_modules\\pg\\lib\\client.js:356:19)\n    at Connection.emit (node:events:518:28)\n    at Connection.emit (node:domain:489:12)\n    at D:\\Resume _Generator\\backend\\node_modules\\pg\\lib\\connection.js:116:12\n    at Parser.parse (D:\\Resume _Generator\\backend\\node_modules\\pg-protocol\\src\\parser.ts:103:9)\n    at Socket.<anonymous> (D:\\Resume _Generator\\backend\\node_modules\\pg-protocol\\src\\index.ts:7:48)\n    at Socket.emit (node:events:518:28)\n    at Socket.emit (node:domain:489:12)","timestamp":"2025-09-04T12:49:51.564Z"}
{"level":"error","message":"❌ PostgreSQL connection failed: password authentication failed for user \"username\"","name":"SequelizeConnectionError","original":{"code":"28P01","file":"auth.c","length":104,"line":"332","name":"error","routine":"auth_failed","severity":"FATAL"},"parent":{"code":"28P01","file":"auth.c","length":104,"line":"332","name":"error","routine":"auth_failed","severity":"FATAL"},"service":"cv-builder-api","stack":"SequelizeConnectionError: password authentication failed for user \"username\"\n    at Client._connectionCallback (D:\\Resume _Generator\\backend\\node_modules\\sequelize\\src\\dialects\\postgres\\connection-manager.js:196:24)\n    at Client._handleErrorWhileConnecting (D:\\Resume _Generator\\backend\\node_modules\\pg\\lib\\client.js:336:19)\n    at Client._handleErrorMessage (D:\\Resume _Generator\\backend\\node_modules\\pg\\lib\\client.js:356:19)\n    at Connection.emit (node:events:518:28)\n    at Connection.emit (node:domain:489:12)\n    at D:\\Resume _Generator\\backend\\node_modules\\pg\\lib\\connection.js:116:12\n    at Parser.parse (D:\\Resume _Generator\\backend\\node_modules\\pg-protocol\\src\\parser.ts:103:9)\n    at Socket.<anonymous> (D:\\Resume _Generator\\backend\\node_modules\\pg-protocol\\src\\index.ts:7:48)\n    at Socket.emit (node:events:518:28)\n    at Socket.emit (node:domain:489:12)","timestamp":"2025-09-04T13:54:24.049Z"}
{"level":"error","message":"❌ PostgreSQL connection failed: password authentication failed for user \"username\"","name":"SequelizeConnectionError","original":{"code":"28P01","file":"auth.c","length":104,"line":"332","name":"error","routine":"auth_failed","severity":"FATAL"},"parent":{"code":"28P01","file":"auth.c","length":104,"line":"332","name":"error","routine":"auth_failed","severity":"FATAL"},"service":"cv-builder-api","stack":"SequelizeConnectionError: password authentication failed for user \"username\"\n    at Client._connectionCallback (D:\\Resume _Generator\\backend\\node_modules\\sequelize\\src\\dialects\\postgres\\connection-manager.js:196:24)\n    at Client._handleErrorWhileConnecting (D:\\Resume _Generator\\backend\\node_modules\\pg\\lib\\client.js:336:19)\n    at Client._handleErrorMessage (D:\\Resume _Generator\\backend\\node_modules\\pg\\lib\\client.js:356:19)\n    at Connection.emit (node:events:518:28)\n    at Connection.emit (node:domain:489:12)\n    at D:\\Resume _Generator\\backend\\node_modules\\pg\\lib\\connection.js:116:12\n    at Parser.parse (D:\\Resume _Generator\\backend\\node_modules\\pg-protocol\\src\\parser.ts:103:9)\n    at Socket.<anonymous> (D:\\Resume _Generator\\backend\\node_modules\\pg-protocol\\src\\index.ts:7:48)\n    at Socket.emit (node:events:518:28)\n    at Socket.emit (node:domain:489:12)","timestamp":"2025-09-04T13:55:41.826Z"}
{"level":"error","message":"❌ PostgreSQL connection failed: password authentication failed for user \"username\"","name":"SequelizeConnectionError","original":{"code":"28P01","file":"auth.c","length":104,"line":"332","name":"error","routine":"auth_failed","severity":"FATAL"},"parent":{"code":"28P01","file":"auth.c","length":104,"line":"332","name":"error","routine":"auth_failed","severity":"FATAL"},"service":"cv-builder-api","stack":"SequelizeConnectionError: password authentication failed for user \"username\"\n    at Client._connectionCallback (D:\\Resume _Generator\\backend\\node_modules\\sequelize\\src\\dialects\\postgres\\connection-manager.js:196:24)\n    at Client._handleErrorWhileConnecting (D:\\Resume _Generator\\backend\\node_modules\\pg\\lib\\client.js:336:19)\n    at Client._handleErrorMessage (D:\\Resume _Generator\\backend\\node_modules\\pg\\lib\\client.js:356:19)\n    at Connection.emit (node:events:518:28)\n    at Connection.emit (node:domain:489:12)\n    at D:\\Resume _Generator\\backend\\node_modules\\pg\\lib\\connection.js:116:12\n    at Parser.parse (D:\\Resume _Generator\\backend\\node_modules\\pg-protocol\\src\\parser.ts:103:9)\n    at Socket.<anonymous> (D:\\Resume _Generator\\backend\\node_modules\\pg-protocol\\src\\index.ts:7:48)\n    at Socket.emit (node:events:518:28)\n    at Socket.emit (node:domain:489:12)","timestamp":"2025-09-04T13:59:27.789Z"}
{"level":"error","message":"❌ PostgreSQL connection failed: password authentication failed for user \"username\"","name":"SequelizeConnectionError","original":{"code":"28P01","file":"auth.c","length":104,"line":"332","name":"error","routine":"auth_failed","severity":"FATAL"},"parent":{"code":"28P01","file":"auth.c","length":104,"line":"332","name":"error","routine":"auth_failed","severity":"FATAL"},"service":"cv-builder-api","stack":"SequelizeConnectionError: password authentication failed for user \"username\"\n    at Client._connectionCallback (D:\\Resume _Generator\\backend\\node_modules\\sequelize\\src\\dialects\\postgres\\connection-manager.js:196:24)\n    at Client._handleErrorWhileConnecting (D:\\Resume _Generator\\backend\\node_modules\\pg\\lib\\client.js:336:19)\n    at Client._handleErrorMessage (D:\\Resume _Generator\\backend\\node_modules\\pg\\lib\\client.js:356:19)\n    at Connection.emit (node:events:518:28)\n    at Connection.emit (node:domain:489:12)\n    at D:\\Resume _Generator\\backend\\node_modules\\pg\\lib\\connection.js:116:12\n    at Parser.parse (D:\\Resume _Generator\\backend\\node_modules\\pg-protocol\\src\\parser.ts:103:9)\n    at Socket.<anonymous> (D:\\Resume _Generator\\backend\\node_modules\\pg-protocol\\src\\index.ts:7:48)\n    at Socket.emit (node:events:518:28)\n    at Socket.emit (node:domain:489:12)","timestamp":"2025-09-04T14:03:22.197Z"}
{"level":"error","message":"❌ PostgreSQL connection failed: password authentication failed for user \"username\"","name":"SequelizeConnectionError","original":{"code":"28P01","file":"auth.c","length":104,"line":"332","name":"error","routine":"auth_failed","severity":"FATAL"},"parent":{"code":"28P01","file":"auth.c","length":104,"line":"332","name":"error","routine":"auth_failed","severity":"FATAL"},"service":"cv-builder-api","stack":"SequelizeConnectionError: password authentication failed for user \"username\"\n    at Client._connectionCallback (D:\\Resume _Generator\\backend\\node_modules\\sequelize\\src\\dialects\\postgres\\connection-manager.js:196:24)\n    at Client._handleErrorWhileConnecting (D:\\Resume _Generator\\backend\\node_modules\\pg\\lib\\client.js:336:19)\n    at Client._handleErrorMessage (D:\\Resume _Generator\\backend\\node_modules\\pg\\lib\\client.js:356:19)\n    at Connection.emit (node:events:518:28)\n    at Connection.emit (node:domain:489:12)\n    at D:\\Resume _Generator\\backend\\node_modules\\pg\\lib\\connection.js:116:12\n    at Parser.parse (D:\\Resume _Generator\\backend\\node_modules\\pg-protocol\\src\\parser.ts:103:9)\n    at Socket.<anonymous> (D:\\Resume _Generator\\backend\\node_modules\\pg-protocol\\src\\index.ts:7:48)\n    at Socket.emit (node:events:518:28)\n    at Socket.emit (node:domain:489:12)","timestamp":"2025-09-04T14:06:45.893Z"}
{"level":"error","message":"❌ PostgreSQL connection failed: password authentication failed for user \"username\"","name":"SequelizeConnectionError","original":{"code":"28P01","file":"auth.c","length":104,"line":"332","name":"error","routine":"auth_failed","severity":"FATAL"},"parent":{"code":"28P01","file":"auth.c","length":104,"line":"332","name":"error","routine":"auth_failed","severity":"FATAL"},"service":"cv-builder-api","stack":"SequelizeConnectionError: password authentication failed for user \"username\"\n    at Client._connectionCallback (D:\\Resume _Generator\\backend\\node_modules\\sequelize\\src\\dialects\\postgres\\connection-manager.js:196:24)\n    at Client._handleErrorWhileConnecting (D:\\Resume _Generator\\backend\\node_modules\\pg\\lib\\client.js:336:19)\n    at Client._handleErrorMessage (D:\\Resume _Generator\\backend\\node_modules\\pg\\lib\\client.js:356:19)\n    at Connection.emit (node:events:518:28)\n    at Connection.emit (node:domain:489:12)\n    at D:\\Resume _Generator\\backend\\node_modules\\pg\\lib\\connection.js:116:12\n    at Parser.parse (D:\\Resume _Generator\\backend\\node_modules\\pg-protocol\\src\\parser.ts:103:9)\n    at Socket.<anonymous> (D:\\Resume _Generator\\backend\\node_modules\\pg-protocol\\src\\index.ts:7:48)\n    at Socket.emit (node:events:518:28)\n    at Socket.emit (node:domain:489:12)","timestamp":"2025-09-04T14:08:58.738Z"}
{"level":"error","message":"❌ PostgreSQL connection failed: password authentication failed for user \"username\"","name":"SequelizeConnectionError","original":{"code":"28P01","file":"auth.c","length":104,"line":"332","name":"error","routine":"auth_failed","severity":"FATAL"},"parent":{"code":"28P01","file":"auth.c","length":104,"line":"332","name":"error","routine":"auth_failed","severity":"FATAL"},"service":"cv-builder-api","stack":"SequelizeConnectionError: password authentication failed for user \"username\"\n    at Client._connectionCallback (D:\\Resume _Generator\\backend\\node_modules\\sequelize\\src\\dialects\\postgres\\connection-manager.js:196:24)\n    at Client._handleErrorWhileConnecting (D:\\Resume _Generator\\backend\\node_modules\\pg\\lib\\client.js:336:19)\n    at Client._handleErrorMessage (D:\\Resume _Generator\\backend\\node_modules\\pg\\lib\\client.js:356:19)\n    at Connection.emit (node:events:518:28)\n    at Connection.emit (node:domain:489:12)\n    at D:\\Resume _Generator\\backend\\node_modules\\pg\\lib\\connection.js:116:12\n    at Parser.parse (D:\\Resume _Generator\\backend\\node_modules\\pg-protocol\\src\\parser.ts:103:9)\n    at Socket.<anonymous> (D:\\Resume _Generator\\backend\\node_modules\\pg-protocol\\src\\index.ts:7:48)\n    at Socket.emit (node:events:518:28)\n    at Socket.emit (node:domain:489:12)","timestamp":"2025-09-04T14:09:16.291Z"}
{"level":"error","message":"❌ PostgreSQL connection failed: permission denied for schema public","name":"SequelizeDatabaseError","original":{"code":"42501","file":"aclchk.c","length":99,"line":"2845","name":"error","position":"28","routine":"aclcheck_error","severity":"ERROR","sql":"CREATE TABLE IF NOT EXISTS \"users\" (\"id\" UUID , \"name\" VARCHAR(100) NOT NULL, \"email\" VARCHAR(255) NOT NULL UNIQUE, \"password\" VARCHAR(255) NOT NULL, \"avatar\" VARCHAR(255), \"profession\" VARCHAR(100), \"isVerified\" BOOLEAN DEFAULT false, \"resetPasswordToken\" VARCHAR(255), \"resetPasswordExpires\" TIMESTAMP WITH TIME ZONE, \"createdAt\" TIMESTAMP WITH TIME ZONE NOT NULL, \"updatedAt\" TIMESTAMP WITH TIME ZONE NOT NULL, PRIMARY KEY (\"id\"));"},"parameters":{},"parent":{"code":"42501","file":"aclchk.c","length":99,"line":"2845","name":"error","position":"28","routine":"aclcheck_error","severity":"ERROR","sql":"CREATE TABLE IF NOT EXISTS \"users\" (\"id\" UUID , \"name\" VARCHAR(100) NOT NULL, \"email\" VARCHAR(255) NOT NULL UNIQUE, \"password\" VARCHAR(255) NOT NULL, \"avatar\" VARCHAR(255), \"profession\" VARCHAR(100), \"isVerified\" BOOLEAN DEFAULT false, \"resetPasswordToken\" VARCHAR(255), \"resetPasswordExpires\" TIMESTAMP WITH TIME ZONE, \"createdAt\" TIMESTAMP WITH TIME ZONE NOT NULL, \"updatedAt\" TIMESTAMP WITH TIME ZONE NOT NULL, PRIMARY KEY (\"id\"));"},"service":"cv-builder-api","sql":"CREATE TABLE IF NOT EXISTS \"users\" (\"id\" UUID , \"name\" VARCHAR(100) NOT NULL, \"email\" VARCHAR(255) NOT NULL UNIQUE, \"password\" VARCHAR(255) NOT NULL, \"avatar\" VARCHAR(255), \"profession\" VARCHAR(100), \"isVerified\" BOOLEAN DEFAULT false, \"resetPasswordToken\" VARCHAR(255), \"resetPasswordExpires\" TIMESTAMP WITH TIME ZONE, \"createdAt\" TIMESTAMP WITH TIME ZONE NOT NULL, \"updatedAt\" TIMESTAMP WITH TIME ZONE NOT NULL, PRIMARY KEY (\"id\"));","stack":"Error\n    at Query.run (D:\\Resume _Generator\\backend\\node_modules\\sequelize\\src\\dialects\\postgres\\query.js:76:25)\n    at D:\\Resume _Generator\\backend\\node_modules\\sequelize\\src\\sequelize.js:650:28\n    at processTicksAndRejections (node:internal/process/task_queues:105:5)\n    at async PostgresQueryInterface.createTable (D:\\Resume _Generator\\backend\\node_modules\\sequelize\\src\\dialects\\abstract\\query-interface.js:229:12)\n    at async Function.sync (D:\\Resume _Generator\\backend\\node_modules\\sequelize\\src\\model.js:1353:7)\n    at async Sequelize.sync (D:\\Resume _Generator\\backend\\node_modules\\sequelize\\src\\sequelize.js:825:9)\n    at async connectDB (D:\\Resume _Generator\\backend\\src\\utils\\database.ts:34:5)","timestamp":"2025-09-04T18:44:48.575Z"}
{"code":"model_not_found","error":{"code":"model_not_found","message":"The model `gpt-4` does not exist or you do not have access to it.","param":null,"type":"invalid_request_error"},"headers":{"alt-svc":"h3=\":443\"; ma=86400","cf-cache-status":"DYNAMIC","cf-ray":"97acdf229b2eacb0-NBO","connection":"keep-alive","content-encoding":"gzip","content-type":"application/json; charset=utf-8","date":"Sat, 06 Sep 2025 09:17:09 GMT","server":"cloudflare","set-cookie":"__cf_bm=4DuXg.ZSHJ.Cy.2KmeG54POsgMPRVgE18OeNtM38eXU-1757150229-1.0.1.1-10JbTgd7jm7zn8HBFb_6Y07zredFko5BHWy8Jq0iN6aQS5iu4r1LoE5.6qMUJsUVKyBpXherZkZ5etDnP2iiDlePjNwDo7m.wp28_GepPxY; path=/; expires=Sat, 06-Sep-25 09:47:09 GMT; domain=.api.openai.com; HttpOnly; Secure; SameSite=None, _cfuvid=4osMRAGVTZQatnWJjqho1LH8mFd5zKhpD1lkw7tgc.E-1757150229982-0.0.1.1-604800000; path=/; domain=.api.openai.com; HttpOnly; Secure; SameSite=None","strict-transport-security":"max-age=31536000; includeSubDomains; preload","transfer-encoding":"chunked","vary":"Origin","x-content-type-options":"nosniff","x-request-id":"req_7ff5320a76e64ef7bf7b8f0117dfb212"},"level":"error","message":"OpenAI Interview Questions Error: 404 The model `gpt-4` does not exist or you do not have access to it.","param":null,"request_id":"req_7ff5320a76e64ef7bf7b8f0117dfb212","service":"cv-builder-api","stack":"Error: 404 The model `gpt-4` does not exist or you do not have access to it.\n    at Function.generate (D:\\Resume _Generator\\backend\\node_modules\\openai\\src\\error.ts:84:14)\n    at OpenAI.makeStatusError (D:\\Resume _Generator\\backend\\node_modules\\openai\\src\\core.ts:462:21)\n    at OpenAI.makeRequest (D:\\Resume _Generator\\backend\\node_modules\\openai\\src\\core.ts:526:24)\n    at processTicksAndRejections (node:internal/process/task_queues:105:5)\n    at async Function.generateInterviewQuestions (D:\\Resume _Generator\\backend\\src\\services\\openaiService.ts:160:24)\n    at async generateInterviewQuestions (D:\\Resume _Generator\\backend\\src\\controllers\\aiController.ts:105:23)","status":404,"timestamp":"2025-09-06T09:17:08.514Z","type":"invalid_request_error"}
{"code":"model_not_found","error":{"code":"model_not_found","message":"The model `gpt-4` does not exist or you do not have access to it.","param":null,"type":"invalid_request_error"},"headers":{"alt-svc":"h3=\":443\"; ma=86400","cf-cache-status":"DYNAMIC","cf-ray":"97ace0180896acaf-NBO","connection":"keep-alive","content-encoding":"gzip","content-type":"application/json; charset=utf-8","date":"Sat, 06 Sep 2025 09:17:49 GMT","server":"cloudflare","set-cookie":"__cf_bm=8UjpSSoJ2Ak.KjbvRuaAhdZgyMBJioWcXCGD2.c0dsA-1757150269-1.0.1.1-HlPUHMSGoTWKy7yJJl8.VCKwj_WxatQG6_z6ywlHT7oYpdjqbE.jqGoxe1hPnB8liqs4ugG0qTAnOQY86LKSwyZZKBBB9GQsyl8wyxynhn4; path=/; expires=Sat, 06-Sep-25 09:47:49 GMT; domain=.api.openai.com; HttpOnly; Secure; SameSite=None, _cfuvid=JcKNfFoZpJquLtU3pzXTSelHC8At9KnHSza1MCi7h10-1757150269543-0.0.1.1-604800000; path=/; domain=.api.openai.com; HttpOnly; Secure; SameSite=None","strict-transport-security":"max-age=31536000; includeSubDomains; preload","transfer-encoding":"chunked","vary":"Origin","x-content-type-options":"nosniff","x-request-id":"req_88371e73f103481289393617b9e7307b"},"level":"error","message":"OpenAI Skill Suggestions Error: 404 The model `gpt-4` does not exist or you do not have access to it.","param":null,"request_id":"req_88371e73f103481289393617b9e7307b","service":"cv-builder-api","stack":"Error: 404 The model `gpt-4` does not exist or you do not have access to it.\n    at Function.generate (D:\\Resume _Generator\\backend\\node_modules\\openai\\src\\error.ts:84:14)\n    at OpenAI.makeStatusError (D:\\Resume _Generator\\backend\\node_modules\\openai\\src\\core.ts:462:21)\n    at OpenAI.makeRequest (D:\\Resume _Generator\\backend\\node_modules\\openai\\src\\core.ts:526:24)\n    at processTicksAndRejections (node:internal/process/task_queues:105:5)\n    at async Function.generateSkillSuggestions (D:\\Resume _Generator\\backend\\src\\services\\openaiService.ts:306:24)\n    at async generateSkillSuggestions (D:\\Resume _Generator\\backend\\src\\controllers\\aiController.ts:194:20)","status":404,"timestamp":"2025-09-06T09:17:47.868Z","type":"invalid_request_error"}
{"code":"model_not_found","error":{"code":"model_not_found","message":"The model `gpt-4` does not exist or you do not have access to it.","param":null,"type":"invalid_request_error"},"headers":{"alt-svc":"h3=\":443\"; ma=86400","cf-cache-status":"DYNAMIC","cf-ray":"97ad3800db03acb0-NBO","connection":"keep-alive","content-encoding":"gzip","content-type":"application/json; charset=utf-8","date":"Sat, 06 Sep 2025 10:17:51 GMT","server":"cloudflare","set-cookie":"__cf_bm=zYzkG_bTiHDq88WIjUZqmNj3G_rGR_LyN08cShPK23c-1757153871-1.0.1.1-vp3AGchF2wVjsLjRDUw7VFBb3POOvAwbtfy.UhQMl81Rax9glc.cnO53I.XIT.OoVMq73fXd3MXDjhO7a785._SZ.2K6Q0_GbJvlxPumOEs; path=/; expires=Sat, 06-Sep-25 10:47:51 GMT; domain=.api.openai.com; HttpOnly; Secure; SameSite=None, _cfuvid=L6YyZBYLZicBsHsxw1Jze1_EmMI_g9i3OI4H6YWUozg-1757153871605-0.0.1.1-604800000; path=/; domain=.api.openai.com; HttpOnly; Secure; SameSite=None","strict-transport-security":"max-age=31536000; includeSubDomains; preload","transfer-encoding":"chunked","vary":"Origin","x-content-type-options":"nosniff","x-request-id":"req_c7f35f3d73214d15926a6e2f3bbd9925"},"level":"error","message":"OpenAI Skill Suggestions Error: 404 The model `gpt-4` does not exist or you do not have access to it.","param":null,"request_id":"req_c7f35f3d73214d15926a6e2f3bbd9925","service":"cv-builder-api","stack":"Error: 404 The model `gpt-4` does not exist or you do not have access to it.\n    at Function.generate (D:\\Resume _Generator\\backend\\node_modules\\openai\\src\\error.ts:84:14)\n    at OpenAI.makeStatusError (D:\\Resume _Generator\\backend\\node_modules\\openai\\src\\core.ts:462:21)\n    at OpenAI.makeRequest (D:\\Resume _Generator\\backend\\node_modules\\openai\\src\\core.ts:526:24)\n    at processTicksAndRejections (node:internal/process/task_queues:105:5)\n    at async Function.generateSkillSuggestions (D:\\Resume _Generator\\backend\\src\\services\\openaiService.ts:306:24)\n    at async generateSkillSuggestions (D:\\Resume _Generator\\backend\\src\\controllers\\aiController.ts:194:20)","status":404,"timestamp":"2025-09-06T10:17:49.875Z","type":"invalid_request_error"}
{"code":"model_not_found","error":{"code":"model_not_found","message":"The model `gpt-4` does not exist or you do not have access to it.","param":null,"type":"invalid_request_error"},"headers":{"alt-svc":"h3=\":443\"; ma=86400","cf-cache-status":"DYNAMIC","cf-ray":"97ad39cbba30acb3-NBO","connection":"keep-alive","content-encoding":"gzip","content-type":"application/json; charset=utf-8","date":"Sat, 06 Sep 2025 10:19:03 GMT","server":"cloudflare","set-cookie":"__cf_bm=UQF92pBNqMfA8rXEdwVsk9p7AmbMxnEi_PY5fNL9ruI-1757153943-1.0.1.1-FWBGfXZMD3y_X47XXMPVx9_ib0fynrA7ryVM1nX7z0MvLDyKHZrqEyZHhPTrmQsRdJFEVnvnqUeH8w86CrmmCpIv5NUIfmJIuOdSjgkVjXE; path=/; expires=Sat, 06-Sep-25 10:49:03 GMT; domain=.api.openai.com; HttpOnly; Secure; SameSite=None, _cfuvid=VKwb5UxyClT234vZyhMKbsRrTRa_ccDFXp7ekAMc62k-1757153943336-0.0.1.1-604800000; path=/; domain=.api.openai.com; HttpOnly; Secure; SameSite=None","strict-transport-security":"max-age=31536000; includeSubDomains; preload","transfer-encoding":"chunked","vary":"Origin","x-content-type-options":"nosniff","x-request-id":"req_7ead2f5fe6104bb1bea37c71d170d4ca"},"level":"error","message":"OpenAI Skill Suggestions Error: 404 The model `gpt-4` does not exist or you do not have access to it.","param":null,"request_id":"req_7ead2f5fe6104bb1bea37c71d170d4ca","service":"cv-builder-api","stack":"Error: 404 The model `gpt-4` does not exist or you do not have access to it.\n    at Function.generate (D:\\Resume _Generator\\backend\\node_modules\\openai\\src\\error.ts:84:14)\n    at OpenAI.makeStatusError (D:\\Resume _Generator\\backend\\node_modules\\openai\\src\\core.ts:462:21)\n    at OpenAI.makeRequest (D:\\Resume _Generator\\backend\\node_modules\\openai\\src\\core.ts:526:24)\n    at processTicksAndRejections (node:internal/process/task_queues:105:5)\n    at async Function.generateSkillSuggestions (D:\\Resume _Generator\\backend\\src\\services\\openaiService.ts:306:24)\n    at async generateSkillSuggestions (D:\\Resume _Generator\\backend\\src\\controllers\\aiController.ts:194:20)","status":404,"timestamp":"2025-09-06T10:19:01.600Z","type":"invalid_request_error"}
{"code":"model_not_found","error":{"code":"model_not_found","message":"The model `gpt-4` does not exist or you do not have access to it.","param":null,"type":"invalid_request_error"},"headers":{"alt-svc":"h3=\":443\"; ma=86400","cf-cache-status":"DYNAMIC","cf-ray":"97ad3ba0dbbdacaf-NBO","connection":"keep-alive","content-encoding":"gzip","content-type":"application/json; charset=utf-8","date":"Sat, 06 Sep 2025 10:20:18 GMT","server":"cloudflare","set-cookie":"__cf_bm=O.9pDPvsKeuNzjcXLddveAk6oEqNeXOYOqXfXrkoD3s-1757154018-1.0.1.1-g9fUNJDNp8qyZ6kQ57ZWtuXsu_AXn9RmHn9FitujR6R7Vl7whqyHTkPguZEiTvuGKUVMiDbzU6p63t0dSup.77koMjJ08DeFMz3c0fYHg.c; path=/; expires=Sat, 06-Sep-25 10:50:18 GMT; domain=.api.openai.com; HttpOnly; Secure; SameSite=None, _cfuvid=9Vh4dFbhbMzGyG.HMhuYWTJAFoDTgYoHGtE.eS1mM7o-1757154018337-0.0.1.1-604800000; path=/; domain=.api.openai.com; HttpOnly; Secure; SameSite=None","strict-transport-security":"max-age=31536000; includeSubDomains; preload","transfer-encoding":"chunked","vary":"Origin","x-content-type-options":"nosniff","x-request-id":"req_f1b0873795504a5b92fc87cd1a55f4f4"},"level":"error","message":"OpenAI ATS Score Error: 404 The model `gpt-4` does not exist or you do not have access to it.","param":null,"request_id":"req_f1b0873795504a5b92fc87cd1a55f4f4","service":"cv-builder-api","stack":"Error: 404 The model `gpt-4` does not exist or you do not have access to it.\n    at Function.generate (D:\\Resume _Generator\\backend\\node_modules\\openai\\src\\error.ts:84:14)\n    at OpenAI.makeStatusError (D:\\Resume _Generator\\backend\\node_modules\\openai\\src\\core.ts:462:21)\n    at OpenAI.makeRequest (D:\\Resume _Generator\\backend\\node_modules\\openai\\src\\core.ts:526:24)\n    at processTicksAndRejections (node:internal/process/task_queues:105:5)\n    at async Function.calculateATSScore (D:\\Resume _Generator\\backend\\src\\services\\openaiService.ts:212:24)\n    at async calculateATSScore (D:\\Resume _Generator\\backend\\src\\controllers\\aiController.ts:135:20)","status":404,"timestamp":"2025-09-06T10:20:16.608Z","type":"invalid_request_error"}
{"code":"model_not_found","error":{"code":"model_not_found","message":"The model `gpt-4` does not exist or you do not have access to it.","param":null,"type":"invalid_request_error"},"headers":{"alt-svc":"h3=\":443\"; ma=86400","cf-cache-status":"DYNAMIC","cf-ray":"97ad96a2fdd8acb3-NBO","connection":"keep-alive","content-encoding":"gzip","content-type":"application/json; charset=utf-8","date":"Sat, 06 Sep 2025 11:22:27 GMT","server":"cloudflare","set-cookie":"__cf_bm=TP.SdMn34gsOoKAn7wmr6aMIk5wRTiMlJFP7pfb.spg-1757157747-1.0.1.1-sCyyaRnnKhdFDdBbzBSveRxqEtyZX5h3oIU4JCthUc_MyInRKmpVJUTu_wTMLrNzC8DX9hR8jWg28lbOF1BOplqIGa13X7dRv52NyASVGfc; path=/; expires=Sat, 06-Sep-25 11:52:27 GMT; domain=.api.openai.com; HttpOnly; Secure; SameSite=None, _cfuvid=9Lo4eUS3u7LTxh39HVMz2bM3hgaea5y6Ef2RrptZR_M-1757157747643-0.0.1.1-604800000; path=/; domain=.api.openai.com; HttpOnly; Secure; SameSite=None","strict-transport-security":"max-age=31536000; includeSubDomains; preload","transfer-encoding":"chunked","vary":"Origin","x-content-type-options":"nosniff","x-request-id":"req_4c9e7209161249889f2db3ffe54509b2"},"level":"error","message":"OpenAI Interview Questions Error: 404 The model `gpt-4` does not exist or you do not have access to it.","param":null,"request_id":"req_4c9e7209161249889f2db3ffe54509b2","service":"cv-builder-api","stack":"Error: 404 The model `gpt-4` does not exist or you do not have access to it.\n    at Function.generate (D:\\Resume _Generator\\backend\\node_modules\\openai\\src\\error.ts:84:14)\n    at OpenAI.makeStatusError (D:\\Resume _Generator\\backend\\node_modules\\openai\\src\\core.ts:462:21)\n    at OpenAI.makeRequest (D:\\Resume _Generator\\backend\\node_modules\\openai\\src\\core.ts:526:24)\n    at processTicksAndRejections (node:internal/process/task_queues:105:5)\n    at async Function.generateInterviewQuestions (D:\\Resume _Generator\\backend\\src\\services\\openaiService.ts:160:24)\n    at async generateInterviewQuestions (D:\\Resume _Generator\\backend\\src\\controllers\\aiController.ts:105:23)","status":404,"timestamp":"2025-09-06T11:22:25.855Z","type":"invalid_request_error"}
{"code":"model_not_found","error":{"code":"model_not_found","message":"The model `gpt-4` does not exist or you do not have access to it.","param":null,"type":"invalid_request_error"},"headers":{"alt-svc":"h3=\":443\"; ma=86400","cf-cache-status":"DYNAMIC","cf-ray":"97ad9aef49beacbb-NBO","connection":"keep-alive","content-encoding":"gzip","content-type":"application/json; charset=utf-8","date":"Sat, 06 Sep 2025 11:25:22 GMT","server":"cloudflare","set-cookie":"__cf_bm=cAK1bsYmOlrsL2b349UhGmcfCC8zDyzMD879ViPMIVI-1757157922-1.0.1.1-PFZWbLsIkuyKAkql06lshzCOGBxxfcGHcc.T9z3jUMcjkeVHgmkqOiQer8w2iwW6KW35YVl149hdbUSyIUSMG9p0Vpu.AB4AKyzLEQVoyZE; path=/; expires=Sat, 06-Sep-25 11:55:22 GMT; domain=.api.openai.com; HttpOnly; Secure; SameSite=None, _cfuvid=odbXb9x7.yD9TpqsW1nYLVwwjsP6eC9Tn02CtaQssy4-1757157922883-0.0.1.1-604800000; path=/; domain=.api.openai.com; HttpOnly; Secure; SameSite=None","strict-transport-security":"max-age=31536000; includeSubDomains; preload","transfer-encoding":"chunked","vary":"Origin","x-content-type-options":"nosniff","x-request-id":"req_fb43af1c046c4572aa692b1bb3a30bcb"},"level":"error","message":"OpenAI Skill Suggestions Error: 404 The model `gpt-4` does not exist or you do not have access to it.","param":null,"request_id":"req_fb43af1c046c4572aa692b1bb3a30bcb","service":"cv-builder-api","stack":"Error: 404 The model `gpt-4` does not exist or you do not have access to it.\n    at Function.generate (D:\\Resume _Generator\\backend\\node_modules\\openai\\src\\error.ts:84:14)\n    at OpenAI.makeStatusError (D:\\Resume _Generator\\backend\\node_modules\\openai\\src\\core.ts:462:21)\n    at OpenAI.makeRequest (D:\\Resume _Generator\\backend\\node_modules\\openai\\src\\core.ts:526:24)\n    at processTicksAndRejections (node:internal/process/task_queues:105:5)\n    at async Function.generateSkillSuggestions (D:\\Resume _Generator\\backend\\src\\services\\openaiService.ts:306:24)\n    at async generateSkillSuggestions (D:\\Resume _Generator\\backend\\src\\controllers\\aiController.ts:194:20)","status":404,"timestamp":"2025-09-06T11:25:21.092Z","type":"invalid_request_error"}
{"code":"model_not_found","error":{"code":"model_not_found","message":"The model `gpt-4` does not exist or you do not have access to it.","param":null,"type":"invalid_request_error"},"headers":{"alt-svc":"h3=\":443\"; ma=86400","cf-cache-status":"DYNAMIC","cf-ray":"97ad9cb759f1acbb-NBO","connection":"keep-alive","content-encoding":"gzip","content-type":"application/json; charset=utf-8","date":"Sat, 06 Sep 2025 11:26:36 GMT","server":"cloudflare","set-cookie":"__cf_bm=_5IM7DSCDH6x8LmSiedsV.GS4eMWBxeVnd7xYiABGy8-1757157996-1.0.1.1-k6FKrVtgfBsALsHh4GNVN5m7Yoye42OmS7Qa_ytHt2Cy0SKioTyX64GkBqAmGzuom59fA9O9enGACM76emJgxZg7VcuBvWyWCxZUmaPfmlI; path=/; expires=Sat, 06-Sep-25 11:56:36 GMT; domain=.api.openai.com; HttpOnly; Secure; SameSite=None, _cfuvid=eOXXIy4M8985jFHq4AXSHmPUPzRRrxzesKEeL7kgRfE-1757157996466-0.0.1.1-604800000; path=/; domain=.api.openai.com; HttpOnly; Secure; SameSite=None","strict-transport-security":"max-age=31536000; includeSubDomains; preload","transfer-encoding":"chunked","vary":"Origin","x-content-type-options":"nosniff","x-request-id":"req_370b7f649d75486ea89160a43bde26b7"},"level":"error","message":"OpenAI Summary Generation Error: 404 The model `gpt-4` does not exist or you do not have access to it.","param":null,"request_id":"req_370b7f649d75486ea89160a43bde26b7","service":"cv-builder-api","stack":"Error: 404 The model `gpt-4` does not exist or you do not have access to it.\n    at Function.generate (D:\\Resume _Generator\\backend\\node_modules\\openai\\src\\error.ts:84:14)\n    at OpenAI.makeStatusError (D:\\Resume _Generator\\backend\\node_modules\\openai\\src\\core.ts:462:21)\n    at OpenAI.makeRequest (D:\\Resume _Generator\\backend\\node_modules\\openai\\src\\core.ts:526:24)\n    at processTicksAndRejections (node:internal/process/task_queues:105:5)\n    at async Function.generateProfessionalSummary (D:\\Resume _Generator\\backend\\src\\services\\openaiService.ts:34:24)\n    at async generateSummary (D:\\Resume _Generator\\backend\\src\\controllers\\aiController.ts:16:21)","status":404,"timestamp":"2025-09-06T11:26:34.677Z","type":"invalid_request_error"}
{"code":"model_not_found","error":{"code":"model_not_found","message":"The model `gpt-4` does not exist or you do not have access to it.","param":null,"type":"invalid_request_error"},"headers":{"alt-svc":"h3=\":443\"; ma=86400","cf-cache-status":"DYNAMIC","cf-ray":"97ad9fd67964acb9-NBO","connection":"keep-alive","content-encoding":"gzip","content-type":"application/json; charset=utf-8","date":"Sat, 06 Sep 2025 11:28:44 GMT","server":"cloudflare","set-cookie":"__cf_bm=f9t5L5285Y4o0lxGHeuBzTAhAseMNBdlDywz.lyB0Vg-1757158124-1.0.1.1-.3IDG5rJesWd9AblokV.MutGynWjsQ19jYOodbXX2CkWvcGz7kkBIYSNcpmo6TVFHrUUiPfumdzY5Y.2LG_4Ed6ldzeaU3p.nyFm08DC2s8; path=/; expires=Sat, 06-Sep-25 11:58:44 GMT; domain=.api.openai.com; HttpOnly; Secure; SameSite=None, _cfuvid=ekhONCsjffXemQt8RjS.T9Mp31mPl.7zu0bQ_CONdTU-1757158124418-0.0.1.1-604800000; path=/; domain=.api.openai.com; HttpOnly; Secure; SameSite=None","strict-transport-security":"max-age=31536000; includeSubDomains; preload","transfer-encoding":"chunked","vary":"Origin","x-content-type-options":"nosniff","x-request-id":"req_adb9735136934e18a864b254ffef03e2"},"level":"error","message":"OpenAI ATS Score Error: 404 The model `gpt-4` does not exist or you do not have access to it.","param":null,"request_id":"req_adb9735136934e18a864b254ffef03e2","service":"cv-builder-api","stack":"Error: 404 The model `gpt-4` does not exist or you do not have access to it.\n    at Function.generate (D:\\Resume _Generator\\backend\\node_modules\\openai\\src\\error.ts:84:14)\n    at OpenAI.makeStatusError (D:\\Resume _Generator\\backend\\node_modules\\openai\\src\\core.ts:462:21)\n    at OpenAI.makeRequest (D:\\Resume _Generator\\backend\\node_modules\\openai\\src\\core.ts:526:24)\n    at processTicksAndRejections (node:internal/process/task_queues:105:5)\n    at async Function.calculateATSScore (D:\\Resume _Generator\\backend\\src\\services\\openaiService.ts:212:24)\n    at async calculateATSScore (D:\\Resume _Generator\\backend\\src\\controllers\\aiController.ts:135:20)","status":404,"timestamp":"2025-09-06T11:28:42.623Z","type":"invalid_request_error"}
{"level":"error","message":"❌ PostgreSQL connection failed: cannot drop column user_id of table cvs because other objects depend on it","name":"SequelizeDatabaseError","original":{"code":"2BP01","detail":"policy Users can view own CVs on table cvs depends on column user_id of table cvs\npolicy Users can create own CVs on table cvs depends on column user_id of table cvs\npolicy Users can update own CVs on table cvs depends on column user_id of table cvs\npolicy Users can delete own CVs on table cvs depends on column user_id of table cvs","file":"dependency.c","hint":"Use DROP ... CASCADE to drop the dependent objects too.","length":538,"line":"1148","name":"error","routine":"reportDependentObjects","severity":"ERROR","sql":"ALTER TABLE \"public\".\"cvs\" DROP COLUMN \"user_id\";"},"parameters":{},"parent":{"code":"2BP01","detail":"policy Users can view own CVs on table cvs depends on column user_id of table cvs\npolicy Users can create own CVs on table cvs depends on column user_id of table cvs\npolicy Users can update own CVs on table cvs depends on column user_id of table cvs\npolicy Users can delete own CVs on table cvs depends on column user_id of table cvs","file":"dependency.c","hint":"Use DROP ... CASCADE to drop the dependent objects too.","length":538,"line":"1148","name":"error","routine":"reportDependentObjects","severity":"ERROR","sql":"ALTER TABLE \"public\".\"cvs\" DROP COLUMN \"user_id\";"},"service":"cv-builder-api","sql":"ALTER TABLE \"public\".\"cvs\" DROP COLUMN \"user_id\";","stack":"Error\n    at Query.run (D:\\Resume _Generator\\backend\\node_modules\\sequelize\\src\\dialects\\postgres\\query.js:76:25)\n    at D:\\Resume _Generator\\backend\\node_modules\\sequelize\\src\\sequelize.js:650:28\n    at processTicksAndRejections (node:internal/process/task_queues:105:5)\n    at async Function.sync (D:\\Resume _Generator\\backend\\node_modules\\sequelize\\src\\model.js:1382:13)\n    at async Sequelize.sync (D:\\Resume _Generator\\backend\\node_modules\\sequelize\\src\\sequelize.js:825:9)\n    at async connectDB (D:\\Resume _Generator\\backend\\src\\utils\\database.ts:43:5)","timestamp":"2025-09-19T18:55:51.007Z"}
{"level":"error","message":"❌ PostgreSQL connection failed: cannot drop column user_id of table cvs because other objects depend on it","name":"SequelizeDatabaseError","original":{"code":"2BP01","detail":"policy Users can view own CVs on table cvs depends on column user_id of table cvs\npolicy Users can create own CVs on table cvs depends on column user_id of table cvs\npolicy Users can update own CVs on table cvs depends on column user_id of table cvs\npolicy Users can delete own CVs on table cvs depends on column user_id of table cvs","file":"dependency.c","hint":"Use DROP ... CASCADE to drop the dependent objects too.","length":538,"line":"1148","name":"error","routine":"reportDependentObjects","severity":"ERROR","sql":"ALTER TABLE \"public\".\"cvs\" DROP COLUMN \"user_id\";"},"parameters":{},"parent":{"code":"2BP01","detail":"policy Users can view own CVs on table cvs depends on column user_id of table cvs\npolicy Users can create own CVs on table cvs depends on column user_id of table cvs\npolicy Users can update own CVs on table cvs depends on column user_id of table cvs\npolicy Users can delete own CVs on table cvs depends on column user_id of table cvs","file":"dependency.c","hint":"Use DROP ... CASCADE to drop the dependent objects too.","length":538,"line":"1148","name":"error","routine":"reportDependentObjects","severity":"ERROR","sql":"ALTER TABLE \"public\".\"cvs\" DROP COLUMN \"user_id\";"},"service":"cv-builder-api","sql":"ALTER TABLE \"public\".\"cvs\" DROP COLUMN \"user_id\";","stack":"Error\n    at Query.run (D:\\Resume _Generator\\backend\\node_modules\\sequelize\\src\\dialects\\postgres\\query.js:76:25)\n    at D:\\Resume _Generator\\backend\\node_modules\\sequelize\\src\\sequelize.js:650:28\n    at processTicksAndRejections (node:internal/process/task_queues:105:5)\n    at async Function.sync (D:\\Resume _Generator\\backend\\node_modules\\sequelize\\src\\model.js:1382:13)\n    at async Sequelize.sync (D:\\Resume _Generator\\backend\\node_modules\\sequelize\\src\\sequelize.js:825:9)\n    at async connectDB (D:\\Resume _Generator\\backend\\src\\utils\\database.ts:43:5)","timestamp":"2025-09-19T18:58:00.957Z"}
